‚ùå Telegram bot error: Cannot close a running event loop
Traceback (most recent call last):
  File "/opt/venv/lib/python3.12/site-packages/telegram/ext/_application.py", line 1006, in __run
    raise exc
  File "/opt/venv/lib/python3.12/site-packages/telegram/ext/_application.py", line 995, in __run
    loop.run_until_complete(self.initialize())
  File "/root/.nix-profile/lib/python3.12/asyncio/base_events.py", line 663, in run_until_complete
    self._check_running()
  File "/root/.nix-profile/lib/python3.12/asyncio/base_events.py", line 622, in _check_running
    raise RuntimeError('This event loop is already running')
RuntimeError: This event loop is already running
During handling of the above exception, another exception occurred:
Traceback (most recent call last):
  File "/opt/venv/lib/python3.12/site-packages/telegram/ext/_application.py", line 1017, in __run
    loop.run_until_complete(self.shutdown())
  File "/root/.nix-profile/lib/python3.12/asyncio/base_events.py", line 663, in run_until_complete
    self._check_running()
  File "/root/.nix-profile/lib/python3.12/asyncio/base_events.py", line 622, in _check_running
    raise RuntimeError('This event loop is already running')
RuntimeError: This event loop is already running
During handling of the above exception, another exception occurred:
Traceback (most recent call last):
  File "/app/app.py", line 20, in run_telegram_bot
    bot.run_sync()
  File "/app/bot/base_bot.py", line 44, in run_sync
    asyncio.run(self.run())
  File "/root/.nix-profile/lib/python3.12/asyncio/runners.py", line 194, in run
    return runner.run(main)
           ^^^^^^^^^^^^^^^^
  File "/root/.nix-profile/lib/python3.12/asyncio/runners.py", line 118, in run
    return self._loop.run_until_complete(task)
           ^^^^^^^^^^^^^^^^^^^^^^^^^^^^^^^^^^^
  File "/root/.nix-profile/lib/python3.12/asyncio/base_events.py", line 687, in run_until_complete
    return future.result()
           ^^^^^^^^^^^^^^^
  File "/app/bot/base_bot.py", line 37, in run
    await self.application.run_polling(
          ^^^^^^^^^^^^^^^^^^^^^^^^^^^^^
  File "/opt/venv/lib/python3.12/site-packages/telegram/ext/_application.py", line 818, in run_polling
    return self.__run(
           ^^^^^^^^^^^
  File "/opt/venv/lib/python3.12/site-packages/telegram/ext/_application.py", line 1022, in __run
    loop.close()
  File "/root/.nix-profile/lib/python3.12/asyncio/unix_events.py", line 68, in close
    super().close()
  File "/root/.nix-profile/lib/python3.12/asyncio/selector_events.py", line 101, in close
    raise RuntimeError("Cannot close a running event loop")
RuntimeError: Cannot close a running event loop
ü§ñ Starting Telegram bot...
==================================================
ü§ñ Telegram Bot Started
==================================================
Bot is running and waiting for messages...
==================================================
‚ùå Telegram bot error: Cannot close a running event loop
Traceback (most recent call last):
  File "/opt/venv/lib/python3.12/site-packages/telegram/ext/_application.py", line 1006, in __run
    raise exc
  File "/opt/venv/lib/python3.12/site-packages/telegram/ext/_application.py", line 995, in __run
    loop.run_until_complete(self.initialize())
  File "/root/.nix-profile/lib/python3.12/asyncio/base_events.py", line 663, in run_until_complete
    self._check_running()
  File "/root/.nix-profile/lib/python3.12/asyncio/base_events.py", line 622, in _check_running
    raise RuntimeError('This event loop is already running')
RuntimeError: This event loop is already running
During handling of the above exception, another exception occurred:
Traceback (most recent call last):
  File "/opt/venv/lib/python3.12/site-packages/telegram/ext/_application.py", line 1017, in __run
    loop.run_until_complete(self.shutdown())
  File "/root/.nix-profile/lib/python3.12/asyncio/base_events.py", line 663, in run_until_complete
    self._check_running()
  File "/root/.nix-profile/lib/python3.12/asyncio/base_events.py", line 622, in _check_running
    raise RuntimeError('This event loop is already running')
RuntimeError: This event loop is already running
During handling of the above exception, another exception occurred:
Traceback (most recent call last):
  File "/app/app.py", line 20, in run_telegram_bot
    bot.run_sync()
  File "/app/bot/base_bot.py", line 44, in run_sync
    asyncio.run(self.run())
  File "/root/.nix-profile/lib/python3.12/asyncio/runners.py", line 194, in run
    return runner.run(main)
           ^^^^^^^^^^^^^^^^
  File "/root/.nix-profile/lib/python3.12/asyncio/runners.py", line 118, in run
    return self._loop.run_until_complete(task)
           ^^^^^^^^^^^^^^^^^^^^^^^^^^^^^^^^^^^
  File "/root/.nix-profile/lib/python3.12/asyncio/base_events.py", line 687, in run_until_complete
    return future.result()
           ^^^^^^^^^^^^^^^
  File "/app/bot/base_bot.py", line 37, in run
    await self.application.run_polling(
          ^^^^^^^^^^^^^^^^^^^^^^^^^^^^^
  File "/opt/venv/lib/python3.12/site-packages/telegram/ext/_application.py", line 818, in run_polling
    return self.__run(
           ^^^^^^^^^^^
  File "/opt/venv/lib/python3.12/site-packages/telegram/ext/_application.py", line 1022, in __run
    loop.close()
  File "/root/.nix-profile/lib/python3.12/asyncio/unix_events.py", line 68, in close
    super().close()
  File "/root/.nix-profile/lib/python3.12/asyncio/selector_events.py", line 101, in close
    raise RuntimeError("Cannot close a running event loop")
RuntimeError: Cannot close a running event loop
